<sdf version="1.6">
<model name="dogo">

	<!-- ** Links Definitions ** -->
	<!-- * Base Definitions * -->
	<link name="base_link">
		<!-- Position -->
		<pose>0 0 0 0 -0 0</pose>
		<!-- Inertia -->
		<inertial>
			<pose frame=>0 0 0 0 -0 0</pose>
			<mass> 1.8</mass>
			<inertia>
				<ixx>0.029125</ixx>
				<ixy>0</ixy>
				<ixz>0</ixz>
				<iyy>0.029125</iyy>
				<iyz>0</iyz>
				<izz>0.055225</izz>
			</inertia>
		</inertial>		
		<!-- collision -->
		<collision name="base_link_colision">
			<pose frame=>0 0 0 0 -0 0</pose>
			<geometry>
				<cylinder>
					<radius> 0.1 </radius>
					<length> 0.05 </length>
				</cylinder>
			</geometry>
			<surface>
				<contact>
					<ode>
						<min_depth>0.001</min_depth>
						<max_vel>0</max_vel>
					</ode>
				</contact>
				<friction>
					<ode/>
				</friction>
			</surface>
		</collision>		
		<!-- Visual -->
		<visual name="base_link_visual">
			<pose frame=>0 0 0 0 -0 0</pose>
			<geometry>
				<cylinder>
					<radius> 0.1 </radius>
					<length> 0.05 </length>
				</cylinder>
			</geometry>
			<material>
				<script>
					<name>Gazebo/DarkGrey</name>
					<uri>file://media/materials/scripts/gazebo.material</uri>
				</script>
			</material>
			</visual>		
		<gravity>1</gravity>
      		<velocity_decay/>
	</link>
	
	<link name="/imu_link">
		<!-- Position -->
		<pose>0 0 0 0 -0 0</pose>
		<!-- Inertia -->
		<inertial>
			<pose frame=>0 0 0 0 -0 0</pose>
			<mass> 0.015</mass>
			<inertia>
				<ixx>1.0e-05</ixx>
				<ixy>0</ixy>
				<ixz>0</ixz>
				<iyy>1.0e-05</iyy>
				<iyz>0</iyz>
				<izz>1.0e-05</izz>
			</inertia>
		</inertial>		
	</link>
	
	<joint name="imu_joint" type="revolute">
		<child>/imu_link</child>
		<parent>base_link</parent>
		<axis>
			<xyz>1 0 0</xyz>
			<limit>
				<lower>0</lower>
				<upper>0</upper>
			</limit>
			<dynamics>
				<spring_reference>0</spring_reference>
				<spring_stiffness>0</spring_stiffness>
			</dynamics>
			<use_parent_model_frame>1</use_parent_model_frame>
		</axis>
	</joint>	
	
	
					
								
	<link name="leg0_0">
		<!-- Position -->
		<pose>  0 0 0 0 0 0 </pose>
		<!-- Inertia -->
		<inertial>
			<pose frame=>0 0 0 0 -0 0</pose>
			<mass> 1</mass>
			<inertia>
				<ixx>1</ixx>
				<ixy>0</ixy>
				<ixz>0</ixz>
				<iyy>1</iyy>
				<iyz>0</iyz>
				<izz>1</izz>
			</inertia>
		</inertial>		
		<!-- Visual -->
		<visual name="leg0_0_visual">
			<pose frame=>0 0 0 0 -0 0</pose>
			<geometry>
				<mesh>
					<scale>1 1 1</scale>
					<uri>model://leg0.stl</uri>
				</mesh>
			</geometry>
			<material>
				<script>
					<name>Gazebo/DarkGrey</name>
					<uri>file://media/materials/scripts/gazebo.material</uri>
				</script>
			</material>
			</visual>		
	</link>
	<joint name="leg0_0_joint" type="revolute">
		<child>leg0_0</child>
		<parent>base_link</parent>
		<axis>
			<xyz>0 0 1</xyz>
			<limit>
				<lower>-1.0e+16</lower>
				<upper>1.0e+16</upper>
			</limit>
			<dynamics>
				<spring_reference>0</spring_reference>
				<spring_stiffness>0</spring_stiffness>
			</dynamics>
			<use_parent_model_frame>1</use_parent_model_frame>
		</axis>
	</joint>
								
	<link name="leg1_0">
		<!-- Position -->
		<pose>  0 0 0 0 0 0 </pose>
		<!-- Inertia -->
		<inertial>
			<pose frame=>0 0 0 0 -0 0</pose>
			<mass> 1</mass>
			<inertia>
				<ixx>1</ixx>
				<ixy>0</ixy>
				<ixz>0</ixz>
				<iyy>1</iyy>
				<iyz>0</iyz>
				<izz>1</izz>
			</inertia>
		</inertial>		
		<!-- Visual -->
		<visual name="leg1_0_visual">
			<pose frame=>0 0 0 0 -0 0</pose>
			<geometry>
				<mesh>
					<scale>1 1 1</scale>
					<uri>model://leg1.stl</uri>
				</mesh>
			</geometry>
			<material>
				<script>
					<name>Gazebo/DarkGrey</name>
					<uri>file://media/materials/scripts/gazebo.material</uri>
				</script>
			</material>
			</visual>		
	</link>
	<joint name="leg1_0_joint" type="revolute">
		<child>leg1_0</child>
		<parent>base_link</parent>
		<axis>
			<xyz>0 0 1</xyz>
			<limit>
				<lower>-1.0e+16</lower>
				<upper>1.0e+16</upper>
			</limit>
			<dynamics>
				<spring_reference>0</spring_reference>
				<spring_stiffness>0</spring_stiffness>
			</dynamics>
			<use_parent_model_frame>1</use_parent_model_frame>
		</axis>
	</joint>
								
	<link name="leg2_0">
		<!-- Position -->
		<pose>  0 0 0 0 0 0 </pose>
		<!-- Inertia -->
		<inertial>
			<pose frame=>0 0 0 0 -0 0</pose>
			<mass> 1</mass>
			<inertia>
				<ixx>1</ixx>
				<ixy>0</ixy>
				<ixz>0</ixz>
				<iyy>1</iyy>
				<iyz>0</iyz>
				<izz>1</izz>
			</inertia>
		</inertial>		
		<!-- Visual -->
		<visual name="leg2_0_visual">
			<pose frame=>0 0 0 0 -0 0</pose>
			<geometry>
				<mesh>
					<scale>1 1 1</scale>
					<uri>model://leg2.stl</uri>
				</mesh>
			</geometry>
			<material>
				<script>
					<name>Gazebo/DarkGrey</name>
					<uri>file://media/materials/scripts/gazebo.material</uri>
				</script>
			</material>
			</visual>		
	</link>
	<joint name="leg2_0_joint" type="revolute">
		<child>leg2_0</child>
		<parent>base_link</parent>
		<axis>
			<xyz>0 0 1</xyz>
			<limit>
				<lower>-1.0e+16</lower>
				<upper>1.0e+16</upper>
			</limit>
			<dynamics>
				<spring_reference>0</spring_reference>
				<spring_stiffness>0</spring_stiffness>
			</dynamics>
			<use_parent_model_frame>1</use_parent_model_frame>
		</axis>
	</joint>
								
	<link name="leg3_0">
		<!-- Position -->
		<pose>  0 0 0 0 0 0 </pose>
		<!-- Inertia -->
		<inertial>
			<pose frame=>0 0 0 0 -0 0</pose>
			<mass> 1</mass>
			<inertia>
				<ixx>1</ixx>
				<ixy>0</ixy>
				<ixz>0</ixz>
				<iyy>1</iyy>
				<iyz>0</iyz>
				<izz>1</izz>
			</inertia>
		</inertial>		
		<!-- Visual -->
		<visual name="leg3_0_visual">
			<pose frame=>0 0 0 0 -0 0</pose>
			<geometry>
				<mesh>
					<scale>1 1 1</scale>
					<uri>model://leg3.stl</uri>
				</mesh>
			</geometry>
			<material>
				<script>
					<name>Gazebo/DarkGrey</name>
					<uri>file://media/materials/scripts/gazebo.material</uri>
				</script>
			</material>
			</visual>		
	</link>
	<joint name="leg3_0_joint" type="revolute">
		<child>leg3_0</child>
		<parent>base_link</parent>
		<axis>
			<xyz>0 0 1</xyz>
			<limit>
				<lower>-1.0e+16</lower>
				<upper>1.0e+16</upper>
			</limit>
			<dynamics>
				<spring_reference>0</spring_reference>
				<spring_stiffness>0</spring_stiffness>
			</dynamics>
			<use_parent_model_frame>1</use_parent_model_frame>
		</axis>
	</joint>
							
								
	<link name="leg0_1">
		<!-- Position -->
		<pose>  0 0 0 0 0 0 </pose>
		<!-- Inertia -->
		<inertial>
			<pose frame=>0 0 0 0 -0 0</pose>
			<mass> 1</mass>
			<inertia>
				<ixx>1</ixx>
				<ixy>0</ixy>
				<ixz>0</ixz>
				<iyy>1</iyy>
				<iyz>0</iyz>
				<izz>1</izz>
			</inertia>
		</inertial>		
		<!-- Visual -->
		<visual name="leg0_1_visual">
			<pose frame=>0 0 0 0 -0 0</pose>
			<geometry>
				<mesh>
					<scale>1 1 1</scale>
					<uri>model://leg0.stl</uri>
				</mesh>
			</geometry>
			<material>
				<script>
					<name>Gazebo/DarkGrey</name>
					<uri>file://media/materials/scripts/gazebo.material</uri>
				</script>
			</material>
			</visual>		
	</link>
	<joint name="leg0_1_joint" type="revolute">
		<child>leg0_1</child>
		<parent>base_link</parent>
		<axis>
			<xyz>0 0 1</xyz>
			<limit>
				<lower>-1.0e+16</lower>
				<upper>1.0e+16</upper>
			</limit>
			<dynamics>
				<spring_reference>0</spring_reference>
				<spring_stiffness>0</spring_stiffness>
			</dynamics>
			<use_parent_model_frame>1</use_parent_model_frame>
		</axis>
	</joint>
								
	<link name="leg1_1">
		<!-- Position -->
		<pose>  0 0 0 0 0 0 </pose>
		<!-- Inertia -->
		<inertial>
			<pose frame=>0 0 0 0 -0 0</pose>
			<mass> 1</mass>
			<inertia>
				<ixx>1</ixx>
				<ixy>0</ixy>
				<ixz>0</ixz>
				<iyy>1</iyy>
				<iyz>0</iyz>
				<izz>1</izz>
			</inertia>
		</inertial>		
		<!-- Visual -->
		<visual name="leg1_1_visual">
			<pose frame=>0 0 0 0 -0 0</pose>
			<geometry>
				<mesh>
					<scale>1 1 1</scale>
					<uri>model://leg1.stl</uri>
				</mesh>
			</geometry>
			<material>
				<script>
					<name>Gazebo/DarkGrey</name>
					<uri>file://media/materials/scripts/gazebo.material</uri>
				</script>
			</material>
			</visual>		
	</link>
	<joint name="leg1_1_joint" type="revolute">
		<child>leg1_1</child>
		<parent>base_link</parent>
		<axis>
			<xyz>0 0 1</xyz>
			<limit>
				<lower>-1.0e+16</lower>
				<upper>1.0e+16</upper>
			</limit>
			<dynamics>
				<spring_reference>0</spring_reference>
				<spring_stiffness>0</spring_stiffness>
			</dynamics>
			<use_parent_model_frame>1</use_parent_model_frame>
		</axis>
	</joint>
								
	<link name="leg2_1">
		<!-- Position -->
		<pose>  0 0 0 0 0 0 </pose>
		<!-- Inertia -->
		<inertial>
			<pose frame=>0 0 0 0 -0 0</pose>
			<mass> 1</mass>
			<inertia>
				<ixx>1</ixx>
				<ixy>0</ixy>
				<ixz>0</ixz>
				<iyy>1</iyy>
				<iyz>0</iyz>
				<izz>1</izz>
			</inertia>
		</inertial>		
		<!-- Visual -->
		<visual name="leg2_1_visual">
			<pose frame=>0 0 0 0 -0 0</pose>
			<geometry>
				<mesh>
					<scale>1 1 1</scale>
					<uri>model://leg2.stl</uri>
				</mesh>
			</geometry>
			<material>
				<script>
					<name>Gazebo/DarkGrey</name>
					<uri>file://media/materials/scripts/gazebo.material</uri>
				</script>
			</material>
			</visual>		
	</link>
	<joint name="leg2_1_joint" type="revolute">
		<child>leg2_1</child>
		<parent>base_link</parent>
		<axis>
			<xyz>0 0 1</xyz>
			<limit>
				<lower>-1.0e+16</lower>
				<upper>1.0e+16</upper>
			</limit>
			<dynamics>
				<spring_reference>0</spring_reference>
				<spring_stiffness>0</spring_stiffness>
			</dynamics>
			<use_parent_model_frame>1</use_parent_model_frame>
		</axis>
	</joint>
								
	<link name="leg3_1">
		<!-- Position -->
		<pose>  0 0 0 0 0 0 </pose>
		<!-- Inertia -->
		<inertial>
			<pose frame=>0 0 0 0 -0 0</pose>
			<mass> 1</mass>
			<inertia>
				<ixx>1</ixx>
				<ixy>0</ixy>
				<ixz>0</ixz>
				<iyy>1</iyy>
				<iyz>0</iyz>
				<izz>1</izz>
			</inertia>
		</inertial>		
		<!-- Visual -->
		<visual name="leg3_1_visual">
			<pose frame=>0 0 0 0 -0 0</pose>
			<geometry>
				<mesh>
					<scale>1 1 1</scale>
					<uri>model://leg3.stl</uri>
				</mesh>
			</geometry>
			<material>
				<script>
					<name>Gazebo/DarkGrey</name>
					<uri>file://media/materials/scripts/gazebo.material</uri>
				</script>
			</material>
			</visual>		
	</link>
	<joint name="leg3_1_joint" type="revolute">
		<child>leg3_1</child>
		<parent>base_link</parent>
		<axis>
			<xyz>0 0 1</xyz>
			<limit>
				<lower>-1.0e+16</lower>
				<upper>1.0e+16</upper>
			</limit>
			<dynamics>
				<spring_reference>0</spring_reference>
				<spring_stiffness>0</spring_stiffness>
			</dynamics>
			<use_parent_model_frame>1</use_parent_model_frame>
		</axis>
	</joint>
							
								
	<link name="leg0_2">
		<!-- Position -->
		<pose>  0 0 0 0 0 0 </pose>
		<!-- Inertia -->
		<inertial>
			<pose frame=>0 0 0 0 -0 0</pose>
			<mass> 1</mass>
			<inertia>
				<ixx>1</ixx>
				<ixy>0</ixy>
				<ixz>0</ixz>
				<iyy>1</iyy>
				<iyz>0</iyz>
				<izz>1</izz>
			</inertia>
		</inertial>		
		<!-- Visual -->
		<visual name="leg0_2_visual">
			<pose frame=>0 0 0 0 -0 0</pose>
			<geometry>
				<mesh>
					<scale>1 1 1</scale>
					<uri>model://leg0.stl</uri>
				</mesh>
			</geometry>
			<material>
				<script>
					<name>Gazebo/DarkGrey</name>
					<uri>file://media/materials/scripts/gazebo.material</uri>
				</script>
			</material>
			</visual>		
	</link>
	<joint name="leg0_2_joint" type="revolute">
		<child>leg0_2</child>
		<parent>base_link</parent>
		<axis>
			<xyz>0 0 1</xyz>
			<limit>
				<lower>-1.0e+16</lower>
				<upper>1.0e+16</upper>
			</limit>
			<dynamics>
				<spring_reference>0</spring_reference>
				<spring_stiffness>0</spring_stiffness>
			</dynamics>
			<use_parent_model_frame>1</use_parent_model_frame>
		</axis>
	</joint>
								
	<link name="leg1_2">
		<!-- Position -->
		<pose>  0 0 0 0 0 0 </pose>
		<!-- Inertia -->
		<inertial>
			<pose frame=>0 0 0 0 -0 0</pose>
			<mass> 1</mass>
			<inertia>
				<ixx>1</ixx>
				<ixy>0</ixy>
				<ixz>0</ixz>
				<iyy>1</iyy>
				<iyz>0</iyz>
				<izz>1</izz>
			</inertia>
		</inertial>		
		<!-- Visual -->
		<visual name="leg1_2_visual">
			<pose frame=>0 0 0 0 -0 0</pose>
			<geometry>
				<mesh>
					<scale>1 1 1</scale>
					<uri>model://leg1.stl</uri>
				</mesh>
			</geometry>
			<material>
				<script>
					<name>Gazebo/DarkGrey</name>
					<uri>file://media/materials/scripts/gazebo.material</uri>
				</script>
			</material>
			</visual>		
	</link>
	<joint name="leg1_2_joint" type="revolute">
		<child>leg1_2</child>
		<parent>base_link</parent>
		<axis>
			<xyz>0 0 1</xyz>
			<limit>
				<lower>-1.0e+16</lower>
				<upper>1.0e+16</upper>
			</limit>
			<dynamics>
				<spring_reference>0</spring_reference>
				<spring_stiffness>0</spring_stiffness>
			</dynamics>
			<use_parent_model_frame>1</use_parent_model_frame>
		</axis>
	</joint>
								
	<link name="leg2_2">
		<!-- Position -->
		<pose>  0 0 0 0 0 0 </pose>
		<!-- Inertia -->
		<inertial>
			<pose frame=>0 0 0 0 -0 0</pose>
			<mass> 1</mass>
			<inertia>
				<ixx>1</ixx>
				<ixy>0</ixy>
				<ixz>0</ixz>
				<iyy>1</iyy>
				<iyz>0</iyz>
				<izz>1</izz>
			</inertia>
		</inertial>		
		<!-- Visual -->
		<visual name="leg2_2_visual">
			<pose frame=>0 0 0 0 -0 0</pose>
			<geometry>
				<mesh>
					<scale>1 1 1</scale>
					<uri>model://leg2.stl</uri>
				</mesh>
			</geometry>
			<material>
				<script>
					<name>Gazebo/DarkGrey</name>
					<uri>file://media/materials/scripts/gazebo.material</uri>
				</script>
			</material>
			</visual>		
	</link>
	<joint name="leg2_2_joint" type="revolute">
		<child>leg2_2</child>
		<parent>base_link</parent>
		<axis>
			<xyz>0 0 1</xyz>
			<limit>
				<lower>-1.0e+16</lower>
				<upper>1.0e+16</upper>
			</limit>
			<dynamics>
				<spring_reference>0</spring_reference>
				<spring_stiffness>0</spring_stiffness>
			</dynamics>
			<use_parent_model_frame>1</use_parent_model_frame>
		</axis>
	</joint>
								
	<link name="leg3_2">
		<!-- Position -->
		<pose>  0 0 0 0 0 0 </pose>
		<!-- Inertia -->
		<inertial>
			<pose frame=>0 0 0 0 -0 0</pose>
			<mass> 1</mass>
			<inertia>
				<ixx>1</ixx>
				<ixy>0</ixy>
				<ixz>0</ixz>
				<iyy>1</iyy>
				<iyz>0</iyz>
				<izz>1</izz>
			</inertia>
		</inertial>		
		<!-- Visual -->
		<visual name="leg3_2_visual">
			<pose frame=>0 0 0 0 -0 0</pose>
			<geometry>
				<mesh>
					<scale>1 1 1</scale>
					<uri>model://leg3.stl</uri>
				</mesh>
			</geometry>
			<material>
				<script>
					<name>Gazebo/DarkGrey</name>
					<uri>file://media/materials/scripts/gazebo.material</uri>
				</script>
			</material>
			</visual>		
	</link>
	<joint name="leg3_2_joint" type="revolute">
		<child>leg3_2</child>
		<parent>base_link</parent>
		<axis>
			<xyz>0 0 1</xyz>
			<limit>
				<lower>-1.0e+16</lower>
				<upper>1.0e+16</upper>
			</limit>
			<dynamics>
				<spring_reference>0</spring_reference>
				<spring_stiffness>0</spring_stiffness>
			</dynamics>
			<use_parent_model_frame>1</use_parent_model_frame>
		</axis>
	</joint>
							
								
	<link name="leg0_3">
		<!-- Position -->
		<pose>  0 0 0 0 0 0 </pose>
		<!-- Inertia -->
		<inertial>
			<pose frame=>0 0 0 0 -0 0</pose>
			<mass> 1</mass>
			<inertia>
				<ixx>1</ixx>
				<ixy>0</ixy>
				<ixz>0</ixz>
				<iyy>1</iyy>
				<iyz>0</iyz>
				<izz>1</izz>
			</inertia>
		</inertial>		
		<!-- Visual -->
		<visual name="leg0_3_visual">
			<pose frame=>0 0 0 0 -0 0</pose>
			<geometry>
				<mesh>
					<scale>1 1 1</scale>
					<uri>model://leg0.stl</uri>
				</mesh>
			</geometry>
			<material>
				<script>
					<name>Gazebo/DarkGrey</name>
					<uri>file://media/materials/scripts/gazebo.material</uri>
				</script>
			</material>
			</visual>		
	</link>
	<joint name="leg0_3_joint" type="revolute">
		<child>leg0_3</child>
		<parent>base_link</parent>
		<axis>
			<xyz>0 0 1</xyz>
			<limit>
				<lower>-1.0e+16</lower>
				<upper>1.0e+16</upper>
			</limit>
			<dynamics>
				<spring_reference>0</spring_reference>
				<spring_stiffness>0</spring_stiffness>
			</dynamics>
			<use_parent_model_frame>1</use_parent_model_frame>
		</axis>
	</joint>
								
	<link name="leg1_3">
		<!-- Position -->
		<pose>  0 0 0 0 0 0 </pose>
		<!-- Inertia -->
		<inertial>
			<pose frame=>0 0 0 0 -0 0</pose>
			<mass> 1</mass>
			<inertia>
				<ixx>1</ixx>
				<ixy>0</ixy>
				<ixz>0</ixz>
				<iyy>1</iyy>
				<iyz>0</iyz>
				<izz>1</izz>
			</inertia>
		</inertial>		
		<!-- Visual -->
		<visual name="leg1_3_visual">
			<pose frame=>0 0 0 0 -0 0</pose>
			<geometry>
				<mesh>
					<scale>1 1 1</scale>
					<uri>model://leg1.stl</uri>
				</mesh>
			</geometry>
			<material>
				<script>
					<name>Gazebo/DarkGrey</name>
					<uri>file://media/materials/scripts/gazebo.material</uri>
				</script>
			</material>
			</visual>		
	</link>
	<joint name="leg1_3_joint" type="revolute">
		<child>leg1_3</child>
		<parent>base_link</parent>
		<axis>
			<xyz>0 0 1</xyz>
			<limit>
				<lower>-1.0e+16</lower>
				<upper>1.0e+16</upper>
			</limit>
			<dynamics>
				<spring_reference>0</spring_reference>
				<spring_stiffness>0</spring_stiffness>
			</dynamics>
			<use_parent_model_frame>1</use_parent_model_frame>
		</axis>
	</joint>
								
	<link name="leg2_3">
		<!-- Position -->
		<pose>  0 0 0 0 0 0 </pose>
		<!-- Inertia -->
		<inertial>
			<pose frame=>0 0 0 0 -0 0</pose>
			<mass> 1</mass>
			<inertia>
				<ixx>1</ixx>
				<ixy>0</ixy>
				<ixz>0</ixz>
				<iyy>1</iyy>
				<iyz>0</iyz>
				<izz>1</izz>
			</inertia>
		</inertial>		
		<!-- Visual -->
		<visual name="leg2_3_visual">
			<pose frame=>0 0 0 0 -0 0</pose>
			<geometry>
				<mesh>
					<scale>1 1 1</scale>
					<uri>model://leg2.stl</uri>
				</mesh>
			</geometry>
			<material>
				<script>
					<name>Gazebo/DarkGrey</name>
					<uri>file://media/materials/scripts/gazebo.material</uri>
				</script>
			</material>
			</visual>		
	</link>
	<joint name="leg2_3_joint" type="revolute">
		<child>leg2_3</child>
		<parent>base_link</parent>
		<axis>
			<xyz>0 0 1</xyz>
			<limit>
				<lower>-1.0e+16</lower>
				<upper>1.0e+16</upper>
			</limit>
			<dynamics>
				<spring_reference>0</spring_reference>
				<spring_stiffness>0</spring_stiffness>
			</dynamics>
			<use_parent_model_frame>1</use_parent_model_frame>
		</axis>
	</joint>
								
	<link name="leg3_3">
		<!-- Position -->
		<pose>  0 0 0 0 0 0 </pose>
		<!-- Inertia -->
		<inertial>
			<pose frame=>0 0 0 0 -0 0</pose>
			<mass> 1</mass>
			<inertia>
				<ixx>1</ixx>
				<ixy>0</ixy>
				<ixz>0</ixz>
				<iyy>1</iyy>
				<iyz>0</iyz>
				<izz>1</izz>
			</inertia>
		</inertial>		
		<!-- Visual -->
		<visual name="leg3_3_visual">
			<pose frame=>0 0 0 0 -0 0</pose>
			<geometry>
				<mesh>
					<scale>1 1 1</scale>
					<uri>model://leg3.stl</uri>
				</mesh>
			</geometry>
			<material>
				<script>
					<name>Gazebo/DarkGrey</name>
					<uri>file://media/materials/scripts/gazebo.material</uri>
				</script>
			</material>
			</visual>		
	</link>
	<joint name="leg3_3_joint" type="revolute">
		<child>leg3_3</child>
		<parent>base_link</parent>
		<axis>
			<xyz>0 0 1</xyz>
			<limit>
				<lower>-1.0e+16</lower>
				<upper>1.0e+16</upper>
			</limit>
			<dynamics>
				<spring_reference>0</spring_reference>
				<spring_stiffness>0</spring_stiffness>
			</dynamics>
			<use_parent_model_frame>1</use_parent_model_frame>
		</axis>
	</joint>
				

	
</model>
</sdf>

