

<sdf version="1.6">
<model name="dogo">

	<!-- ** Links Definitions ** -->
	<!-- * Base Definitions * -->
	<link name="base_link">
		<!-- Position -->
		<pose>0.032 0.037 0.09 0 -0 0</pose>
		<!-- Inertia -->
		<!-- <inertial>
			<mass> 0.005</mass>
			<pose>0 0 0 0 0 0</pose>
			<inertia>
				<ixx>0.029125</ixx>
				<ixy>0</ixy>
				<ixz>0</ixz>
				<iyy>0.029125</iyy>
				<iyz>0</iyz>
				<izz>0.055225</izz>
			</inertia>
		</inertial> -->
		
		<!-- collision -->
		<collision name="base_link_colision">
			<pose relative_to=> 0 0 0 0 0 0 </pose>
			<geometry>
			<box>
	                    <size> 0.06 0.02 0.005 </size>
	 		</box>	    
			</geometry>
			<surface>
				<contact>
					<ode>
						<min_depth>0.001</min_depth>
						<max_vel>0</max_vel>
					</ode>
				</contact>
				<friction>
					<ode/>
				</friction>
			</surface>
		</collision>		
		<!-- Visual -->
		<visual name="base_link_visual">
			<pose frame=>0 0 0 0 -0 0</pose>
			<geometry>
			<box>
	                    <size> 0.06 0.02 0.005 </size>
	 		</box>	    
			</geometry>
			<material>
				<script>
					<name>Gazebo/DarkGrey</name>
					<uri>file://media/materials/scripts/gazebo.material</uri>
				</script>
			</material>
		</visual>		
		<gravity>1</gravity>
      		<velocity_decay/>
	</link>
	
	
	
	
					
								
	<link name="leg3_0">
		<!-- Position -->
		<pose>  -0.02 0.019 0.068 0 3.141592653589793 0.0 </pose>
		<!-- Inertia -->
		<inertial>
			<mass> 0.00965</mass>
			<pose>0.00791 0.01831 0 0 0 0</pose>
			<inertia>
				<ixx>1.556e-06</ixx>
				<ixy>1.76e-07</ixy>
				<ixz>0.0</ixz>
				<iyy>3.3e-07</iyy>
				<iyz>0.0</iyz>
				<izz>1.577e-06</izz>
			</inertia>
		</inertial>
		<!-- collision -->
		<collision name="leg3_0_colision">
			<pose relative_to=leg3_0> 0.01 0.02 0 1.5707963267948966 0 0 </pose>
			<geometry>
			<box>
	                    <size> 0.012 0.012 0.055 </size>
	 		</box>	    
			</geometry>
			<surface>
				<contact>
					<ode>
						<min_depth>0.001</min_depth>
						<max_vel>0</max_vel>
					</ode>
				</contact>
				<friction>
					<ode/>
				</friction>
			</surface>
		</collision>		
		<!-- Visual -->
		<visual name="leg3_0_visual">
			<pose relative_to=leg3_0> 0 -0.0075 0.03 3.141592653589793 0 1.5707963267948966 </pose>
			<geometry>
				<mesh>
					<scale>0.001 0.001 0.001</scale>
					<uri>model://dogo/full_leg3.STL</uri>
				</mesh>
			</geometry>
			<material>
				<script>
					<name>Gazebo/DarkGrey</name>
					<uri>file://media/materials/scripts/gazebo.material</uri>
				</script>
			</material>
		</visual>		
	</link>

		
	<joint name="leg3_0_fixed_joint" type="fixed">
		<child>leg3_0</child>
		<parent>base_link</parent>
		<axis>
			<xyz>1 0 0</xyz>
			<limit>
				<lower>-1.0e+16</lower>
				<upper>1.0e+16</upper>
			</limit>
			<dynamics>
				<spring_reference>0</spring_reference>
				<spring_stiffness>0</spring_stiffness>
			</dynamics>
			<use_parent_model_frame>1</use_parent_model_frame>
		</axis>
	</joint>
	
	
	
								
	<link name="leg2_0">
		<!-- Position -->
		<pose>  0.0 0.018 0.068 0 3.141592653589793 0.0 </pose>
		<!-- Inertia -->
		<inertial>
			<mass> 0.00859</mass>
			<pose>0.00784 0.00829 0 0 0 0</pose>
			<inertia>
				<ixx>4.74e-07</ixx>
				<ixy>1.7e-07</ixy>
				<ixz>0</ixz>
				<iyy>6.06e-07</iyy>
				<iyz>0</iyz>
				<izz>8.97e-07</izz>
			</inertia>
		</inertial>
		<!-- collision -->
		<collision name="leg2_0_colision">
			<pose relative_to=leg2_0> 0 0.005 0 0 1.5707963267948966 0 </pose>
			<geometry>
			<box>
	                    <size> 0.02 0.02 0.04 </size>
	 		</box>	    
			</geometry>
			<surface>
				<contact>
					<ode>
						<min_depth>0.001</min_depth>
						<max_vel>0</max_vel>
					</ode>
				</contact>
				<friction>
					<ode/>
				</friction>
			</surface>
		</collision>		
		<!-- Visual -->
		<visual name="leg2_0_visual">
			<pose relative_to=leg2_0> -0.02 0.02 0.0438 3.141592653589793 0 0 </pose>
			<geometry>
				<mesh>
					<scale>0.001 0.001 0.001</scale>
					<uri>model://dogo/full_leg2.STL</uri>
				</mesh>
			</geometry>
			<material>
				<script>
					<name>Gazebo/DarkGrey</name>
					<uri>file://media/materials/scripts/gazebo.material</uri>
				</script>
			</material>
		</visual>		
	</link>

	
	<joint name="leg2_0_joint" type="revolute">
		<child>leg2_0</child>
		<parent>leg3_0</parent>
		<axis>
			<xyz>1 0 0</xyz>
			<limit>
				<lower>-1.0e+16</lower>
				<upper>1.0e+16</upper>
			</limit>
			<dynamics>
				<spring_reference>0</spring_reference>
				<spring_stiffness>0</spring_stiffness>
			</dynamics>
			<use_parent_model_frame>1</use_parent_model_frame>
		</axis>
	</joint>
	
	
	
								
	<link name="leg1_0">
		<!-- Position -->
		<pose>  0.0 0.012 0.068 0 3.141592653589793 0.0 </pose>
		<!-- Inertia -->
		<inertial>
			<mass> 0.00871</mass>
			<pose>-0.00023 -0.0078 0.015 0 0 0</pose>
			<inertia>
				<ixx>1.328e-06</ixx>
				<ixy>5.0e-09</ixy>
				<ixz>1.4e-08</ixz>
				<iyy>1.249e-06</iyy>
				<iyz>1.32e-07</iyz>
				<izz>2.62e-07</izz>
			</inertia>
		</inertial>
		<!-- collision -->
		<collision name="leg1_0_colision">
			<pose relative_to=leg1_0> 0 -0.004 0.015 0 0 0 </pose>
			<geometry>
			<box>
	                    <size> 0.015 0.015 0.043 </size>
	 		</box>	    
			</geometry>
			<surface>
				<contact>
					<ode>
						<min_depth>0.001</min_depth>
						<max_vel>0</max_vel>
					</ode>
				</contact>
				<friction>
					<ode/>
				</friction>
			</surface>
		</collision>		
		<!-- Visual -->
		<visual name="leg1_0_visual">
			<pose relative_to=leg1_0> -0.0305 -0.016 0.04 0 1.5707963267948966 0 </pose>
			<geometry>
				<mesh>
					<scale>0.001 0.001 0.001</scale>
					<uri>model://dogo/full_leg1.STL</uri>
				</mesh>
			</geometry>
			<material>
				<script>
					<name>Gazebo/DarkGrey</name>
					<uri>file://media/materials/scripts/gazebo.material</uri>
				</script>
			</material>
		</visual>		
	</link>

	
	<joint name="leg1_0_joint" type="revolute">
		<child>leg1_0</child>
		<parent>leg2_0</parent>
		<axis>
			<xyz>0 1 0</xyz>
			<limit>
				<lower>-1.0e+16</lower>
				<upper>1.0e+16</upper>
			</limit>
			<dynamics>
				<spring_reference>0</spring_reference>
				<spring_stiffness>0</spring_stiffness>
			</dynamics>
			<use_parent_model_frame>1</use_parent_model_frame>
		</axis>
	</joint>
	
	
	
								
	<link name="leg0_0">
		<!-- Position -->
		<pose>  0.0 0.0 0.035 0 3.141592653589793 0.0 </pose>
		<!-- Inertia -->
		<inertial>
			<mass> 0.00131</mass>
			<pose>0.00132 0.00471 0.013 0 0 0</pose>
			<inertia>
				<ixx>1.091e-06</ixx>
				<ixy>-7.0e-09</ixy>
				<ixz>-1.19e-07</ixz>
				<iyy>2.73e-07</iyy>
				<iyz>1.1e-08</iyz>
				<izz>9.3e-08</izz>
			</inertia>
		</inertial>
		<!-- collision -->
		<collision name="leg0_0_colision">
			<pose relative_to=leg0_0> 0 0.01 0.015 -0.5235987755982988 0.0  </pose>
			<geometry>
			<box>
	                    <size> 0.01 0.01 0.04 </size>
	 		</box>	    
			</geometry>
			<surface>
				<contact>
					<ode>
						<min_depth>0.001</min_depth>
						<max_vel>0</max_vel>
					</ode>
				</contact>
				<friction>
					<ode/>
				</friction>
			</surface>
		</collision>		
		<!-- Visual -->
		<visual name="leg0_0_visual">
			<pose relative_to=leg0_0> -0.004 0.02 -0.0045 0 0 -1.5707963267948966 </pose>
			<geometry>
				<mesh>
					<scale>0.001 0.001 0.001</scale>
					<uri>model://dogo/full_leg0.STL</uri>
				</mesh>
			</geometry>
			<material>
				<script>
					<name>Gazebo/DarkGrey</name>
					<uri>file://media/materials/scripts/gazebo.material</uri>
				</script>
			</material>
		</visual>		
	</link>

	
	<joint name="leg0_0_joint" type="revolute">
		<child>leg0_0</child>
		<parent>leg1_0</parent>
		<axis>
			<xyz>0 1 0</xyz>
			<limit>
				<lower>-1.0e+16</lower>
				<upper>1.0e+16</upper>
			</limit>
			<dynamics>
				<spring_reference>0</spring_reference>
				<spring_stiffness>0</spring_stiffness>
			</dynamics>
			<use_parent_model_frame>1</use_parent_model_frame>
		</axis>
	</joint>
	
	
	
							
								
	<link name="leg3_1">
		<!-- Position -->
		<pose>  0.0161 0.05499999999999999 0.068 0 3.141592653589793 3.141592653589793 </pose>
		<!-- Inertia -->
		<inertial>
			<mass> 0.00965</mass>
			<pose>0.00791 0.01831 0 0 0 0</pose>
			<inertia>
				<ixx>1.556e-06</ixx>
				<ixy>1.76e-07</ixy>
				<ixz>0.0</ixz>
				<iyy>3.3e-07</iyy>
				<iyz>0.0</iyz>
				<izz>1.577e-06</izz>
			</inertia>
		</inertial>
		<!-- collision -->
		<collision name="leg3_1_colision">
			<pose relative_to=leg3_1> 0.01 0.02 0 1.5707963267948966 0 0 </pose>
			<geometry>
			<box>
	                    <size> 0.012 0.012 0.055 </size>
	 		</box>	    
			</geometry>
			<surface>
				<contact>
					<ode>
						<min_depth>0.001</min_depth>
						<max_vel>0</max_vel>
					</ode>
				</contact>
				<friction>
					<ode/>
				</friction>
			</surface>
		</collision>		
		<!-- Visual -->
		<visual name="leg3_1_visual">
			<pose relative_to=leg3_1> 0 -0.0075 0.03 3.141592653589793 0 1.5707963267948966 </pose>
			<geometry>
				<mesh>
					<scale>0.001 0.001 0.001</scale>
					<uri>model://dogo/full_leg3.STL</uri>
				</mesh>
			</geometry>
			<material>
				<script>
					<name>Gazebo/DarkGrey</name>
					<uri>file://media/materials/scripts/gazebo.material</uri>
				</script>
			</material>
		</visual>		
	</link>

		
	<joint name="leg3_1_fixed_joint" type="fixed">
		<child>leg3_1</child>
		<parent>base_link</parent>
		<axis>
			<xyz>1 0 0</xyz>
			<limit>
				<lower>-1.0e+16</lower>
				<upper>1.0e+16</upper>
			</limit>
			<dynamics>
				<spring_reference>0</spring_reference>
				<spring_stiffness>0</spring_stiffness>
			</dynamics>
			<use_parent_model_frame>1</use_parent_model_frame>
		</axis>
	</joint>
	
	
	
								
	<link name="leg2_1">
		<!-- Position -->
		<pose>  -0.0039 0.055999999999999994 0.068 0 3.141592653589793 3.141592653589793 </pose>
		<!-- Inertia -->
		<inertial>
			<mass> 0.00859</mass>
			<pose>0.00784 0.00829 0 0 0 0</pose>
			<inertia>
				<ixx>4.74e-07</ixx>
				<ixy>1.7e-07</ixy>
				<ixz>0</ixz>
				<iyy>6.06e-07</iyy>
				<iyz>0</iyz>
				<izz>8.97e-07</izz>
			</inertia>
		</inertial>
		<!-- collision -->
		<collision name="leg2_1_colision">
			<pose relative_to=leg2_1> 0 0.005 0 0 1.5707963267948966 0 </pose>
			<geometry>
			<box>
	                    <size> 0.02 0.02 0.04 </size>
	 		</box>	    
			</geometry>
			<surface>
				<contact>
					<ode>
						<min_depth>0.001</min_depth>
						<max_vel>0</max_vel>
					</ode>
				</contact>
				<friction>
					<ode/>
				</friction>
			</surface>
		</collision>		
		<!-- Visual -->
		<visual name="leg2_1_visual">
			<pose relative_to=leg2_1> -0.02 0.02 0.0438 3.141592653589793 0 0 </pose>
			<geometry>
				<mesh>
					<scale>0.001 0.001 0.001</scale>
					<uri>model://dogo/full_leg2.STL</uri>
				</mesh>
			</geometry>
			<material>
				<script>
					<name>Gazebo/DarkGrey</name>
					<uri>file://media/materials/scripts/gazebo.material</uri>
				</script>
			</material>
		</visual>		
	</link>

	
	<joint name="leg2_1_joint" type="revolute">
		<child>leg2_1</child>
		<parent>leg3_1</parent>
		<axis>
			<xyz>1 0 0</xyz>
			<limit>
				<lower>-1.0e+16</lower>
				<upper>1.0e+16</upper>
			</limit>
			<dynamics>
				<spring_reference>0</spring_reference>
				<spring_stiffness>0</spring_stiffness>
			</dynamics>
			<use_parent_model_frame>1</use_parent_model_frame>
		</axis>
	</joint>
	
	
	
								
	<link name="leg1_1">
		<!-- Position -->
		<pose>  -0.0039 0.062 0.068 0 3.141592653589793 3.141592653589793 </pose>
		<!-- Inertia -->
		<inertial>
			<mass> 0.00871</mass>
			<pose>-0.00023 -0.0078 0.015 0 0 0</pose>
			<inertia>
				<ixx>1.328e-06</ixx>
				<ixy>5.0e-09</ixy>
				<ixz>1.4e-08</ixz>
				<iyy>1.249e-06</iyy>
				<iyz>1.32e-07</iyz>
				<izz>2.62e-07</izz>
			</inertia>
		</inertial>
		<!-- collision -->
		<collision name="leg1_1_colision">
			<pose relative_to=leg1_1> 0 -0.004 0.015 0 0 0 </pose>
			<geometry>
			<box>
	                    <size> 0.015 0.015 0.043 </size>
	 		</box>	    
			</geometry>
			<surface>
				<contact>
					<ode>
						<min_depth>0.001</min_depth>
						<max_vel>0</max_vel>
					</ode>
				</contact>
				<friction>
					<ode/>
				</friction>
			</surface>
		</collision>		
		<!-- Visual -->
		<visual name="leg1_1_visual">
			<pose relative_to=leg1_1> -0.0305 -0.016 0.04 0 1.5707963267948966 0 </pose>
			<geometry>
				<mesh>
					<scale>0.001 0.001 0.001</scale>
					<uri>model://dogo/full_leg1.STL</uri>
				</mesh>
			</geometry>
			<material>
				<script>
					<name>Gazebo/DarkGrey</name>
					<uri>file://media/materials/scripts/gazebo.material</uri>
				</script>
			</material>
		</visual>		
	</link>

	
	<joint name="leg1_1_joint" type="revolute">
		<child>leg1_1</child>
		<parent>leg2_1</parent>
		<axis>
			<xyz>0 1 0</xyz>
			<limit>
				<lower>-1.0e+16</lower>
				<upper>1.0e+16</upper>
			</limit>
			<dynamics>
				<spring_reference>0</spring_reference>
				<spring_stiffness>0</spring_stiffness>
			</dynamics>
			<use_parent_model_frame>1</use_parent_model_frame>
		</axis>
	</joint>
	
	
	
								
	<link name="leg0_1">
		<!-- Position -->
		<pose>  -0.0039 0.074 0.035 0 3.141592653589793 3.141592653589793 </pose>
		<!-- Inertia -->
		<inertial>
			<mass> 0.00131</mass>
			<pose>0.00132 0.00471 0.013 0 0 0</pose>
			<inertia>
				<ixx>1.091e-06</ixx>
				<ixy>-7.0e-09</ixy>
				<ixz>-1.19e-07</ixz>
				<iyy>2.73e-07</iyy>
				<iyz>1.1e-08</iyz>
				<izz>9.3e-08</izz>
			</inertia>
		</inertial>
		<!-- collision -->
		<collision name="leg0_1_colision">
			<pose relative_to=leg0_1> 0 0.01 0.015 -0.5235987755982988 0.0  </pose>
			<geometry>
			<box>
	                    <size> 0.01 0.01 0.04 </size>
	 		</box>	    
			</geometry>
			<surface>
				<contact>
					<ode>
						<min_depth>0.001</min_depth>
						<max_vel>0</max_vel>
					</ode>
				</contact>
				<friction>
					<ode/>
				</friction>
			</surface>
		</collision>		
		<!-- Visual -->
		<visual name="leg0_1_visual">
			<pose relative_to=leg0_1> -0.004 0.02 -0.0045 0 0 -1.5707963267948966 </pose>
			<geometry>
				<mesh>
					<scale>0.001 0.001 0.001</scale>
					<uri>model://dogo/full_leg0.STL</uri>
				</mesh>
			</geometry>
			<material>
				<script>
					<name>Gazebo/DarkGrey</name>
					<uri>file://media/materials/scripts/gazebo.material</uri>
				</script>
			</material>
		</visual>		
	</link>

	
	<joint name="leg0_1_joint" type="revolute">
		<child>leg0_1</child>
		<parent>leg1_1</parent>
		<axis>
			<xyz>0 1 0</xyz>
			<limit>
				<lower>-1.0e+16</lower>
				<upper>1.0e+16</upper>
			</limit>
			<dynamics>
				<spring_reference>0</spring_reference>
				<spring_stiffness>0</spring_stiffness>
			</dynamics>
			<use_parent_model_frame>1</use_parent_model_frame>
		</axis>
	</joint>
	
	
	
							
								
	<link name="leg3_2">
		<!-- Position -->
		<pose>  0.05 0.019 0.068 0 3.141592653589793 0.0 </pose>
		<!-- Inertia -->
		<inertial>
			<mass> 0.00965</mass>
			<pose>0.00791 0.01831 0 0 0 0</pose>
			<inertia>
				<ixx>1.556e-06</ixx>
				<ixy>1.76e-07</ixy>
				<ixz>0.0</ixz>
				<iyy>3.3e-07</iyy>
				<iyz>0.0</iyz>
				<izz>1.577e-06</izz>
			</inertia>
		</inertial>
		<!-- collision -->
		<collision name="leg3_2_colision">
			<pose relative_to=leg3_2> 0.01 0.02 0 1.5707963267948966 0 0 </pose>
			<geometry>
			<box>
	                    <size> 0.012 0.012 0.055 </size>
	 		</box>	    
			</geometry>
			<surface>
				<contact>
					<ode>
						<min_depth>0.001</min_depth>
						<max_vel>0</max_vel>
					</ode>
				</contact>
				<friction>
					<ode/>
				</friction>
			</surface>
		</collision>		
		<!-- Visual -->
		<visual name="leg3_2_visual">
			<pose relative_to=leg3_2> 0 -0.0075 0.03 3.141592653589793 0 1.5707963267948966 </pose>
			<geometry>
				<mesh>
					<scale>0.001 0.001 0.001</scale>
					<uri>model://dogo/full_leg3.STL</uri>
				</mesh>
			</geometry>
			<material>
				<script>
					<name>Gazebo/DarkGrey</name>
					<uri>file://media/materials/scripts/gazebo.material</uri>
				</script>
			</material>
		</visual>		
	</link>

		
	<joint name="leg3_2_fixed_joint" type="fixed">
		<child>leg3_2</child>
		<parent>base_link</parent>
		<axis>
			<xyz>1 0 0</xyz>
			<limit>
				<lower>-1.0e+16</lower>
				<upper>1.0e+16</upper>
			</limit>
			<dynamics>
				<spring_reference>0</spring_reference>
				<spring_stiffness>0</spring_stiffness>
			</dynamics>
			<use_parent_model_frame>1</use_parent_model_frame>
		</axis>
	</joint>
	
	
	
								
	<link name="leg2_2">
		<!-- Position -->
		<pose>  0.07 0.018 0.068 0 3.141592653589793 0.0 </pose>
		<!-- Inertia -->
		<inertial>
			<mass> 0.00859</mass>
			<pose>0.00784 0.00829 0 0 0 0</pose>
			<inertia>
				<ixx>4.74e-07</ixx>
				<ixy>1.7e-07</ixy>
				<ixz>0</ixz>
				<iyy>6.06e-07</iyy>
				<iyz>0</iyz>
				<izz>8.97e-07</izz>
			</inertia>
		</inertial>
		<!-- collision -->
		<collision name="leg2_2_colision">
			<pose relative_to=leg2_2> 0 0.005 0 0 1.5707963267948966 0 </pose>
			<geometry>
			<box>
	                    <size> 0.02 0.02 0.04 </size>
	 		</box>	    
			</geometry>
			<surface>
				<contact>
					<ode>
						<min_depth>0.001</min_depth>
						<max_vel>0</max_vel>
					</ode>
				</contact>
				<friction>
					<ode/>
				</friction>
			</surface>
		</collision>		
		<!-- Visual -->
		<visual name="leg2_2_visual">
			<pose relative_to=leg2_2> -0.02 0.02 0.0438 3.141592653589793 0 0 </pose>
			<geometry>
				<mesh>
					<scale>0.001 0.001 0.001</scale>
					<uri>model://dogo/full_leg2.STL</uri>
				</mesh>
			</geometry>
			<material>
				<script>
					<name>Gazebo/DarkGrey</name>
					<uri>file://media/materials/scripts/gazebo.material</uri>
				</script>
			</material>
		</visual>		
	</link>

	
	<joint name="leg2_2_joint" type="revolute">
		<child>leg2_2</child>
		<parent>leg3_2</parent>
		<axis>
			<xyz>1 0 0</xyz>
			<limit>
				<lower>-1.0e+16</lower>
				<upper>1.0e+16</upper>
			</limit>
			<dynamics>
				<spring_reference>0</spring_reference>
				<spring_stiffness>0</spring_stiffness>
			</dynamics>
			<use_parent_model_frame>1</use_parent_model_frame>
		</axis>
	</joint>
	
	
	
								
	<link name="leg1_2">
		<!-- Position -->
		<pose>  0.07 0.012 0.068 0 3.141592653589793 0.0 </pose>
		<!-- Inertia -->
		<inertial>
			<mass> 0.00871</mass>
			<pose>-0.00023 -0.0078 0.015 0 0 0</pose>
			<inertia>
				<ixx>1.328e-06</ixx>
				<ixy>5.0e-09</ixy>
				<ixz>1.4e-08</ixz>
				<iyy>1.249e-06</iyy>
				<iyz>1.32e-07</iyz>
				<izz>2.62e-07</izz>
			</inertia>
		</inertial>
		<!-- collision -->
		<collision name="leg1_2_colision">
			<pose relative_to=leg1_2> 0 -0.004 0.015 0 0 0 </pose>
			<geometry>
			<box>
	                    <size> 0.015 0.015 0.043 </size>
	 		</box>	    
			</geometry>
			<surface>
				<contact>
					<ode>
						<min_depth>0.001</min_depth>
						<max_vel>0</max_vel>
					</ode>
				</contact>
				<friction>
					<ode/>
				</friction>
			</surface>
		</collision>		
		<!-- Visual -->
		<visual name="leg1_2_visual">
			<pose relative_to=leg1_2> -0.0305 -0.016 0.04 0 1.5707963267948966 0 </pose>
			<geometry>
				<mesh>
					<scale>0.001 0.001 0.001</scale>
					<uri>model://dogo/full_leg1.STL</uri>
				</mesh>
			</geometry>
			<material>
				<script>
					<name>Gazebo/DarkGrey</name>
					<uri>file://media/materials/scripts/gazebo.material</uri>
				</script>
			</material>
		</visual>		
	</link>

	
	<joint name="leg1_2_joint" type="revolute">
		<child>leg1_2</child>
		<parent>leg2_2</parent>
		<axis>
			<xyz>0 1 0</xyz>
			<limit>
				<lower>-1.0e+16</lower>
				<upper>1.0e+16</upper>
			</limit>
			<dynamics>
				<spring_reference>0</spring_reference>
				<spring_stiffness>0</spring_stiffness>
			</dynamics>
			<use_parent_model_frame>1</use_parent_model_frame>
		</axis>
	</joint>
	
	
	
								
	<link name="leg0_2">
		<!-- Position -->
		<pose>  0.07 0.0 0.035 0 3.141592653589793 0.0 </pose>
		<!-- Inertia -->
		<inertial>
			<mass> 0.00131</mass>
			<pose>0.00132 0.00471 0.013 0 0 0</pose>
			<inertia>
				<ixx>1.091e-06</ixx>
				<ixy>-7.0e-09</ixy>
				<ixz>-1.19e-07</ixz>
				<iyy>2.73e-07</iyy>
				<iyz>1.1e-08</iyz>
				<izz>9.3e-08</izz>
			</inertia>
		</inertial>
		<!-- collision -->
		<collision name="leg0_2_colision">
			<pose relative_to=leg0_2> 0 0.01 0.015 -0.5235987755982988 0.0  </pose>
			<geometry>
			<box>
	                    <size> 0.01 0.01 0.04 </size>
	 		</box>	    
			</geometry>
			<surface>
				<contact>
					<ode>
						<min_depth>0.001</min_depth>
						<max_vel>0</max_vel>
					</ode>
				</contact>
				<friction>
					<ode/>
				</friction>
			</surface>
		</collision>		
		<!-- Visual -->
		<visual name="leg0_2_visual">
			<pose relative_to=leg0_2> -0.004 0.02 -0.0045 0 0 -1.5707963267948966 </pose>
			<geometry>
				<mesh>
					<scale>0.001 0.001 0.001</scale>
					<uri>model://dogo/full_leg0.STL</uri>
				</mesh>
			</geometry>
			<material>
				<script>
					<name>Gazebo/DarkGrey</name>
					<uri>file://media/materials/scripts/gazebo.material</uri>
				</script>
			</material>
		</visual>		
	</link>

	
	<joint name="leg0_2_joint" type="revolute">
		<child>leg0_2</child>
		<parent>leg1_2</parent>
		<axis>
			<xyz>0 1 0</xyz>
			<limit>
				<lower>-1.0e+16</lower>
				<upper>1.0e+16</upper>
			</limit>
			<dynamics>
				<spring_reference>0</spring_reference>
				<spring_stiffness>0</spring_stiffness>
			</dynamics>
			<use_parent_model_frame>1</use_parent_model_frame>
		</axis>
	</joint>
	
	
	
							
								
	<link name="leg3_3">
		<!-- Position -->
		<pose>  0.08610000000000001 0.05499999999999999 0.068 0 3.141592653589793 3.141592653589793 </pose>
		<!-- Inertia -->
		<inertial>
			<mass> 0.00965</mass>
			<pose>0.00791 0.01831 0 0 0 0</pose>
			<inertia>
				<ixx>1.556e-06</ixx>
				<ixy>1.76e-07</ixy>
				<ixz>0.0</ixz>
				<iyy>3.3e-07</iyy>
				<iyz>0.0</iyz>
				<izz>1.577e-06</izz>
			</inertia>
		</inertial>
		<!-- collision -->
		<collision name="leg3_3_colision">
			<pose relative_to=leg3_3> 0.01 0.02 0 1.5707963267948966 0 0 </pose>
			<geometry>
			<box>
	                    <size> 0.012 0.012 0.055 </size>
	 		</box>	    
			</geometry>
			<surface>
				<contact>
					<ode>
						<min_depth>0.001</min_depth>
						<max_vel>0</max_vel>
					</ode>
				</contact>
				<friction>
					<ode/>
				</friction>
			</surface>
		</collision>		
		<!-- Visual -->
		<visual name="leg3_3_visual">
			<pose relative_to=leg3_3> 0 -0.0075 0.03 3.141592653589793 0 1.5707963267948966 </pose>
			<geometry>
				<mesh>
					<scale>0.001 0.001 0.001</scale>
					<uri>model://dogo/full_leg3.STL</uri>
				</mesh>
			</geometry>
			<material>
				<script>
					<name>Gazebo/DarkGrey</name>
					<uri>file://media/materials/scripts/gazebo.material</uri>
				</script>
			</material>
		</visual>		
	</link>

		
	<joint name="leg3_3_fixed_joint" type="fixed">
		<child>leg3_3</child>
		<parent>base_link</parent>
		<axis>
			<xyz>1 0 0</xyz>
			<limit>
				<lower>-1.0e+16</lower>
				<upper>1.0e+16</upper>
			</limit>
			<dynamics>
				<spring_reference>0</spring_reference>
				<spring_stiffness>0</spring_stiffness>
			</dynamics>
			<use_parent_model_frame>1</use_parent_model_frame>
		</axis>
	</joint>
	
	
	
								
	<link name="leg2_3">
		<!-- Position -->
		<pose>  0.0661 0.055999999999999994 0.068 0 3.141592653589793 3.141592653589793 </pose>
		<!-- Inertia -->
		<inertial>
			<mass> 0.00859</mass>
			<pose>0.00784 0.00829 0 0 0 0</pose>
			<inertia>
				<ixx>4.74e-07</ixx>
				<ixy>1.7e-07</ixy>
				<ixz>0</ixz>
				<iyy>6.06e-07</iyy>
				<iyz>0</iyz>
				<izz>8.97e-07</izz>
			</inertia>
		</inertial>
		<!-- collision -->
		<collision name="leg2_3_colision">
			<pose relative_to=leg2_3> 0 0.005 0 0 1.5707963267948966 0 </pose>
			<geometry>
			<box>
	                    <size> 0.02 0.02 0.04 </size>
	 		</box>	    
			</geometry>
			<surface>
				<contact>
					<ode>
						<min_depth>0.001</min_depth>
						<max_vel>0</max_vel>
					</ode>
				</contact>
				<friction>
					<ode/>
				</friction>
			</surface>
		</collision>		
		<!-- Visual -->
		<visual name="leg2_3_visual">
			<pose relative_to=leg2_3> -0.02 0.02 0.0438 3.141592653589793 0 0 </pose>
			<geometry>
				<mesh>
					<scale>0.001 0.001 0.001</scale>
					<uri>model://dogo/full_leg2.STL</uri>
				</mesh>
			</geometry>
			<material>
				<script>
					<name>Gazebo/DarkGrey</name>
					<uri>file://media/materials/scripts/gazebo.material</uri>
				</script>
			</material>
		</visual>		
	</link>

	
	<joint name="leg2_3_joint" type="revolute">
		<child>leg2_3</child>
		<parent>leg3_3</parent>
		<axis>
			<xyz>1 0 0</xyz>
			<limit>
				<lower>-1.0e+16</lower>
				<upper>1.0e+16</upper>
			</limit>
			<dynamics>
				<spring_reference>0</spring_reference>
				<spring_stiffness>0</spring_stiffness>
			</dynamics>
			<use_parent_model_frame>1</use_parent_model_frame>
		</axis>
	</joint>
	
	
	
								
	<link name="leg1_3">
		<!-- Position -->
		<pose>  0.0661 0.062 0.068 0 3.141592653589793 3.141592653589793 </pose>
		<!-- Inertia -->
		<inertial>
			<mass> 0.00871</mass>
			<pose>-0.00023 -0.0078 0.015 0 0 0</pose>
			<inertia>
				<ixx>1.328e-06</ixx>
				<ixy>5.0e-09</ixy>
				<ixz>1.4e-08</ixz>
				<iyy>1.249e-06</iyy>
				<iyz>1.32e-07</iyz>
				<izz>2.62e-07</izz>
			</inertia>
		</inertial>
		<!-- collision -->
		<collision name="leg1_3_colision">
			<pose relative_to=leg1_3> 0 -0.004 0.015 0 0 0 </pose>
			<geometry>
			<box>
	                    <size> 0.015 0.015 0.043 </size>
	 		</box>	    
			</geometry>
			<surface>
				<contact>
					<ode>
						<min_depth>0.001</min_depth>
						<max_vel>0</max_vel>
					</ode>
				</contact>
				<friction>
					<ode/>
				</friction>
			</surface>
		</collision>		
		<!-- Visual -->
		<visual name="leg1_3_visual">
			<pose relative_to=leg1_3> -0.0305 -0.016 0.04 0 1.5707963267948966 0 </pose>
			<geometry>
				<mesh>
					<scale>0.001 0.001 0.001</scale>
					<uri>model://dogo/full_leg1.STL</uri>
				</mesh>
			</geometry>
			<material>
				<script>
					<name>Gazebo/DarkGrey</name>
					<uri>file://media/materials/scripts/gazebo.material</uri>
				</script>
			</material>
		</visual>		
	</link>

	
	<joint name="leg1_3_joint" type="revolute">
		<child>leg1_3</child>
		<parent>leg2_3</parent>
		<axis>
			<xyz>0 1 0</xyz>
			<limit>
				<lower>-1.0e+16</lower>
				<upper>1.0e+16</upper>
			</limit>
			<dynamics>
				<spring_reference>0</spring_reference>
				<spring_stiffness>0</spring_stiffness>
			</dynamics>
			<use_parent_model_frame>1</use_parent_model_frame>
		</axis>
	</joint>
	
	
	
								
	<link name="leg0_3">
		<!-- Position -->
		<pose>  0.0661 0.074 0.035 0 3.141592653589793 3.141592653589793 </pose>
		<!-- Inertia -->
		<inertial>
			<mass> 0.00131</mass>
			<pose>0.00132 0.00471 0.013 0 0 0</pose>
			<inertia>
				<ixx>1.091e-06</ixx>
				<ixy>-7.0e-09</ixy>
				<ixz>-1.19e-07</ixz>
				<iyy>2.73e-07</iyy>
				<iyz>1.1e-08</iyz>
				<izz>9.3e-08</izz>
			</inertia>
		</inertial>
		<!-- collision -->
		<collision name="leg0_3_colision">
			<pose relative_to=leg0_3> 0 0.01 0.015 -0.5235987755982988 0.0  </pose>
			<geometry>
			<box>
	                    <size> 0.01 0.01 0.04 </size>
	 		</box>	    
			</geometry>
			<surface>
				<contact>
					<ode>
						<min_depth>0.001</min_depth>
						<max_vel>0</max_vel>
					</ode>
				</contact>
				<friction>
					<ode/>
				</friction>
			</surface>
		</collision>		
		<!-- Visual -->
		<visual name="leg0_3_visual">
			<pose relative_to=leg0_3> -0.004 0.02 -0.0045 0 0 -1.5707963267948966 </pose>
			<geometry>
				<mesh>
					<scale>0.001 0.001 0.001</scale>
					<uri>model://dogo/full_leg0.STL</uri>
				</mesh>
			</geometry>
			<material>
				<script>
					<name>Gazebo/DarkGrey</name>
					<uri>file://media/materials/scripts/gazebo.material</uri>
				</script>
			</material>
		</visual>		
	</link>

	
	<joint name="leg0_3_joint" type="revolute">
		<child>leg0_3</child>
		<parent>leg1_3</parent>
		<axis>
			<xyz>0 1 0</xyz>
			<limit>
				<lower>-1.0e+16</lower>
				<upper>1.0e+16</upper>
			</limit>
			<dynamics>
				<spring_reference>0</spring_reference>
				<spring_stiffness>0</spring_stiffness>
			</dynamics>
			<use_parent_model_frame>1</use_parent_model_frame>
		</axis>
	</joint>
	
	
	
				

	
</model>
</sdf>

